Workbook

Sheet Orders
A1: don | B1: order_date | C1: customer_id | D1: city | E1: payment_method | F1: order_amount | G1: order_status | H1: Normalized_Order_ID | I1: Capture_Count | J1: Captured_Amount | K1: Amount_Variance | L1: Reconciliation_Status | N1: Reconciliation Status | O1: Order Count | P1: Total_Order_Value | Q1: Total_Captured_Amount | S1: Order Status | T1: No Capture Count | U1: No Capture Order Value
A2: ORD26000001 | B2: 46286 | C2: CUST28289 | D2: Pune | E2: UPI | F2: 299 | G2: Paid | H2: =UPPER(SUBSTITUTE(TRIM(A2),"-","")) -> ORD26000001 | I2: =COUNTIFS(PG_Transactions!$AK:$AK,$H2,PG_Transactions!$E:$E,"CAPTURE",PG_Transactions!$AQ:$AQ,1) -> 1 | J2: =SUMIFS(PG_Transactions!$G:$G,PG_Transactions!$AK:$AK,$H2,PG_Transactions!$E:$E,"CAPTURE",PG_Transactions!$AQ:$AQ,1) -> 299 | K2: =ROUND(J2-F2,2) -> 0 | L2: =IF(I2=0,"No Capture",IF(I2>1,"Multiple Capture Rows - Review",IF(ABS(K2)<0.01,"Amount Match",IF(K2<0,"Captured Less Than Order","Captured More Than Order")))) -> Amount Match | N2: Amount Match | O2: =COUNTIF($L$2:$L$6001,N2) -> 5464 | P2: =SUMIF($L$2:$L$6001,N2,$F$2:$F$6001) -> 19786999 | Q2: =SUMIF($L$2:$L$6001,N2,$J$2:$J$6001) -> 19786999 | S2: Paid | T2: =COUNTIFS($G$2:$G$6001,S2,$L$2:$L$6001,"No Capture") -> 20 | U2: =SUMIFS($F$2:$F$6001,$G$2:$G$6001,S2,$L$2:$L$6001,"No Capture") -> 67617
A3: ORD26000002 | B3: 46287 | C3: CUST38657 | D3: Bengaluru | E3: UPI | F3: 4647 | G3: Paid | H3: =UPPER(SUBSTITUTE(TRIM(A3),"-","")) -> ORD26000002 | I3: =COUNTIFS(PG_Transactions!$AK:$AK,$H3,PG_Transactions!$E:$E,"CAPTURE",PG_Transactions!$AQ:$AQ,1) -> 1 | J3: =SUMIFS(PG_Transactions!$G:$G,PG_Transactions!$AK:$AK,$H3,PG_Transactions!$E:$E,"CAPTURE",PG_Transactions!$AQ:$AQ,1) -> 4647 | K3: =ROUND(J3-F3,2) -> 0 | L3: =IF(I3=0,"No Capture",IF(I3>1,"Multiple Capture Rows - Review",IF(ABS(K3)<0.01,"Amount Match",IF(K3<0,"Captured Less Than Order","Captured More Than Order")))) -> Amount Match | N3: No Capture | O3: =COUNTIF($L$2:$L$6001,N3) -> 515 | P3: =SUMIF($L$2:$L$6001,N3,$F$2:$F$6001) -> 1873142 | Q3: =SUMIF($L$2:$L$6001,N3,$J$2:$J$6001) -> 0 | S3: Failed | T3: =COUNTIFS($G$2:$G$6001,S3,$L$2:$L$6001,"No Capture") -> 300 | U3: =SUMIFS($F$2:$F$6001,$G$2:$G$6001,S3,$L$2:$L$6001,"No Capture") -> 1088506
A4: ORD26000003 | B4: 46282 | C4: CUST81426 | D4: Kolkata | E4: Card | F4: 2098 | G4: Paid | H4: =UPPER(SUBSTITUTE(TRIM(A4),"-","")) -> ORD26000003 | I4: =COUNTIFS(PG_Transactions!$AK:$AK,$H4,PG_Transactions!$E:$E,"CAPTURE",PG_Transactions!$AQ:$AQ,1) -> 1 | J4: =SUMIFS(PG_Transactions!$G:$G,PG_Transactions!$AK:$AK,$H4,PG_Transactions!$E:$E,"CAPTURE",PG_Transactions!$AQ:$AQ,1) -> 2098 | K4: =ROUND(J4-F4,2) -> 0 | L4: =IF(I4=0,"No Capture",IF(I4>1,"Multiple Capture Rows - Review",IF(ABS(K4)<0.01,"Amount Match",IF(K4<0,"Captured Less Than Order","Captured More Than Order")))) -> Amount Match | N4: Multiple Capture Rows - Review | O4: =COUNTIF($L$2:$L$6001,N4) -> 6 | P4: =SUMIF($L$2:$L$6001,N4,$F$2:$F$6001) -> 25539 | Q4: =SUMIF($L$2:$L$6001,N4,$J$2:$J$6001) -> 51078 | S4: Refunded | T4: =COUNTIFS($G$2:$G$6001,S4,$L$2:$L$6001,"No Capture") -> 0 | U4: =SUMIFS($F$2:$F$6001,$G$2:$G$6001,S4,$L$2:$L$6001,"No Capture") -> 0
A5: ORD26000004 | B5: 46273 | C5: CUST30926 | D5: Kolkata | E5: UPI | F5: 3298 | G5: Paid | H5: =UPPER(SUBSTITUTE(TRIM(A5),"-","")) -> ORD26000004 | I5: =COUNTIFS(PG_Transactions!$AK:$AK,$H5,PG_Transactions!$E:$E,"CAPTURE",PG_Transactions!$AQ:$AQ,1) -> 1 | J5: =SUMIFS(PG_Transactions!$G:$G,PG_Transactions!$AK:$AK,$H5,PG_Transactions!$E:$E,"CAPTURE",PG_Transactions!$AQ:$AQ,1) -> 3298 | K5: =ROUND(J5-F5,2) -> 0 | L5: =IF(I5=0,"No Capture",IF(I5>1,"Multiple Capture Rows - Review",IF(ABS(K5)<0.01,"Amount Match",IF(K5<0,"Captured Less Than Order","Captured More Than Order")))) -> Amount Match | N5: Captured Less Than Order | O5: =COUNTIF($L$2:$L$6001,N5) -> 15 | P5: =SUMIF($L$2:$L$6001,N5,$F$2:$F$6001) -> 42825 | Q5: =SUMIF($L$2:$L$6001,N5,$J$2:$J$6001) -> 39680 | S5: Cancelled | T5: =COUNTIFS($G$2:$G$6001,S5,$L$2:$L$6001,"No Capture") -> 195 | U5: =SUMIFS($F$2:$F$6001,$G$2:$G$6001,S5,$L$2:$L$6001,"No Capture") -> 717019
A6: ORD26000005 | B6: 46276 | C6: CUST23396 | D6: Pune | E6: Card | F6: 499 | G6: Paid | H6: =UPPER(SUBSTITUTE(TRIM(A6),"-","")) -> ORD26000005 | I6: =COUNTIFS(PG_Transactions!$AK:$AK,$H6,PG_Transactions!$E:$E,"CAPTURE",PG_Transactions!$AQ:$AQ,1) -> 1 | J6: =SUMIFS(PG_Transactions!$G:$G,PG_Transactions!$AK:$AK,$H6,PG_Transactions!$E:$E,"CAPTURE",PG_Transactions!$AQ:$AQ,1) -> 499 | K6: =ROUND(J6-F6,2) -> 0 | L6: =IF(I6=0,"No Capture",IF(I6>1,"Multiple Capture Rows - Review",IF(ABS(K6)<0.01,"Amount Match",IF(K6<0,"Captured Less Than Order","Captured More Than Order")))) -> Amount Match | N6: Captured More Than Order | O6: =COUNTIF($L$2:$L$6001,N6) -> 0 | P6: =SUMIF($L$2:$L$6001,N6,$F$2:$F$6001) -> 0 | Q6: =SUMIF($L$2:$L$6001,N6,$J$2:$J$6001) -> 0
A7: ORD26000006 | B7: 46278 | C7: CUST15695 | D7: Ahmedabad | E7: Card | F7: 999 | G7: Paid | H7: =UPPER(SUBSTITUTE(TRIM(A7),"-","")) -> ORD26000006 | I7: =COUNTIFS(PG_Transactions!$AK:$AK,$H7,PG_Transactions!$E:$E,"CAPTURE",PG_Transactions!$AQ:$AQ,1) -> 1 | J7: =SUMIFS(PG_Transactions!$G:$G,PG_Transactions!$AK:$AK,$H7,PG_Transactions!$E:$E,"CAPTURE",PG_Transactions!$AQ:$AQ,1) -> 999 | K7: =ROUND(J7-F7,2) -> 0 | L7: =IF(I7=0,"No Capture",IF(I7>1,"Multiple Capture Rows - Review",IF(ABS(K7)<0.01,"Amount Match",IF(K7<0,"Captured Less Than Order","Captured More Than Order")))) -> Amount Match
A8: ORD26000007 | B8: 46283 | C8: CUST92397 | D8: Lucknow | E8: UPI | F8: 1299 | G8: Paid | H8: =UPPER(SUBSTITUTE(TRIM(A8),"-","")) -> ORD26000007 | I8: =COUNTIFS(PG_Transactions!$AK:$AK,$H8,PG_Transactions!$E:$E,"CAPTURE",PG_Transactions!$AQ:$AQ,1) -> 1 | J8: =SUMIFS(PG_Transactions!$G:$G,PG_Transactions!$AK:$AK,$H8,PG_Transactions!$E:$E,"CAPTURE",PG_Transactions!$AQ:$AQ,1) -> 1299 | K8: =ROUND(J8-F8,2) -> 0 | L8: =IF(I8=0,"No Capture",IF(I8>1,"Multiple Capture Rows - Review",IF(ABS(K8)<0.01,"Amount Match",IF(K8<0,"Captured Less Than Order","Captured More Than Order")))) -> Amount Match
A9: ORD26000008 | B9: 46294 | C9: CUST96673 | D9: Bengaluru | E9: UPI | F9: 2499 | G9: Paid | H9: =UPPER(SUBSTITUTE(TRIM(A9),"-","")) -> ORD26000008 | I9: =COUNTIFS(PG_Transactions!$AK:$AK,$H9,PG_Transactions!$E:$E,"CAPTURE",PG_Transactions!$AQ:$AQ,1) -> 1 | J9: =SUMIFS(PG_Transactions!$G:$G,PG_Transactions!$AK:$AK,$H9,PG_Transactions!$E:$E,"CAPTURE",PG_Transactions!$AQ:$AQ,1) -> 2499 | K9: =ROUND(J9-F9,2) -> 0 | L9: =IF(I9=0,"No Capture",IF(I9>1,"Multiple Capture Rows - Review",IF(ABS(K9)<0.01,"Amount Match",IF(K9<0,"Captured Less Than Order","Captured More Than Order")))) -> Amount Match
A10: ORD26000009 | B10: 46290 | C10: CUST59823 | D10: Hyderabad | E10: NetBanking | F10: 349 | G10: Paid | H10: =UPPER(SUBSTITUTE(TRIM(A10),"-","")) -> ORD26000009 | I10: =COUNTIFS(PG_Transactions!$AK:$AK,$H10,PG_Transactions!$E:$E,"CAPTURE",PG_Transactions!$AQ:$AQ,1) -> 1 | J10: =SUMIFS(PG_Transactions!$G:$G,PG_Transactions!$AK:$AK,$H10,PG_Transactions!$E:$E,"CAPTURE",PG_Transactions!$AQ:$AQ,1) -> 349 | K10: =ROUND(J10-F10,2) -> 0 | L10: =IF(I10=0,"No Capture",IF(I10>1,"Multiple Capture Rows - Review",IF(ABS(K10)<0.01,"Amount Match",IF(K10<0,"Captured Less Than Order","Captured More Than Order")))) -> Amount Match
A11: ORD26000010 | B11: 46280 | C11: CUST44993 | D11: Pune | E11: UPI | F11: 9497 | G11: Paid | H11: =UPPER(SUBSTITUTE(TRIM(A11),"-","")) -> ORD26000010 | I11: =COUNTIFS(PG_Transactions!$AK:$AK,$H11,PG_Transactions!$E:$E,"CAPTURE",PG_Transactions!$AQ:$AQ,1) -> 1 | J11: =SUMIFS(PG_Transactions!$G:$G,PG_Transactions!$AK:$AK,$H11,PG_Transactions!$E:$E,"CAPTURE",PG_Transactions!$AQ:$AQ,1) -> 9497 | K11: =ROUND(J11-F11,2) -> 0 | L11: =IF(I11=0,"No Capture",IF(I11>1,"Multiple Capture Rows - Review",IF(ABS(K11)<0.01,"Amount Match",IF(K11<0,"Captured Less Than Order","Captured More Than Order")))) -> Amount Match
A12: ORD26000011 | B12: 46285 | C12: CUST45382 | D12: Jaipur | E12: UPI | F12: 5797 | G12: Paid | H12: =UPPER(SUBSTITUTE(TRIM(A12),"-","")) -> ORD26000011 | I12: =COUNTIFS(PG_Transactions!$AK:$AK,$H12,PG_Transactions!$E:$E,"CAPTURE",PG_Transactions!$AQ:$AQ,1) -> 1 | J12: =SUMIFS(PG_Transactions!$G:$G,PG_Transactions!$AK:$AK,$H12,PG_Transactions!$E:$E,"CAPTURE",PG_Transactions!$AQ:$AQ,1) -> 5797 | K12: =ROUND(J12-F12,2) -> 0 | L12: =IF(I12=0,"No Capture",IF(I12>1,"Multiple Capture Rows - Review",IF(ABS(K12)<0.01,"Amount Match",IF(K12<0,"Captured Less Than Order","Captured More Than Order")))) -> Amount Match
A13: ORD26000012 | B13: 46273 | C13: CUST14207 | D13: Chennai | E13: UPI | F13: 13997 | G13: Paid | H13: =UPPER(SUBSTITUTE(TRIM(A13),"-","")) -> ORD26000012 | I13: =COUNTIFS(PG_Transactions!$AK:$AK,$H13,PG_Transactions!$E:$E,"CAPTURE",PG_Transactions!$AQ:$AQ,1) -> 1 | J13: =SUMIFS(PG_Transactions!$G:$G,PG_Transactions!$AK:$AK,$H13,PG_Transactions!$E:$E,"CAPTURE",PG_Transactions!$AQ:$AQ,1) -> 13997 | K13: =ROUND(J13-F13,2) -> 0 | L13: =IF(I13=0,"No Capture",IF(I13>1,"Multiple Capture Rows - Review",IF(ABS(K13)<0.01,"Amount Match",IF(K13<0,"Captured Less Than Order","Captured More Than Order")))) -> Amount Match
A14: ORD26000013 | B14: 46278 | C14: CUST51245 | D14: Bengaluru | E14: Wallet | F14: 349 | G14: Paid | H14: =UPPER(SUBSTITUTE(TRIM(A14),"-","")) -> ORD26000013 | I14: =COUNTIFS(PG_Transactions!$AK:$AK,$H14,PG_Transactions!$E:$E,"CAPTURE",PG_Transactions!$AQ:$AQ,1) -> 1 | J14: =SUMIFS(PG_Transactions!$G:$G,PG_Transactions!$AK:$AK,$H14,PG_Transactions!$E:$E,"CAPTURE",PG_Transactions!$AQ:$AQ,1) -> 349 | K14: =ROUND(J14-F14,2) -> 0 | L14: =IF(I14=0,"No Capture",IF(I14>1,"Multiple Capture Rows - Review",IF(ABS(K14)<0.01,"Amount Match",IF(K14<0,"Captured Less Than Order","Captured More Than Order")))) -> Amount Match
A15: ORD26000014 | B15: 46286 | C15: CUST42325 | D15: Jaipur | E15: UPI | F15: 4298 | G15: Paid | H15: =UPPER(SUBSTITUTE(TRIM(A15),"-","")) -> ORD26000014 | I15: =COUNTIFS(PG_Transactions!$AK:$AK,$H15,PG_Transactions!$E:$E,"CAPTURE",PG_Transactions!$AQ:$AQ,1) -> 1 | J15: =SUMIFS(PG_Transactions!$G:$G,PG_Transactions!$AK:$AK,$H15,PG_Transactions!$E:$E,"CAPTURE",PG_Transactions!$AQ:$AQ,1) -> 4298 | K15: =ROUND(J15-F15,2) -> 0 | L15: =IF(I15=0,"No Capture",IF(I15>1,"Multiple Capture Rows - Review",IF(ABS(K15)<0.01,"Amount Match",IF(K15<0,"Captured Less Than Order","Captured More Than Order")))) -> Amount Match
A16: ORD26000015 | B16: 46283 | C16: CUST62350 | D16: Chennai | E16: Wallet | F16: 3499 | G16: Paid | H16: =UPPER(SUBSTITUTE(TRIM(A16),"-","")) -> ORD26000015 | I16: =COUNTIFS(PG_Transactions!$AK:$AK,$H16,PG_Transactions!$E:$E,"CAPTURE",PG_Transactions!$AQ:$AQ,1) -> 1 | J16: =SUMIFS(PG_Transactions!$G:$G,PG_Transactions!$AK:$AK,$H16,PG_Transactions!$E:$E,"CAPTURE",PG_Transactions!$AQ:$AQ,1) -> 3499 | K16: =ROUND(J16-F16,2) -> 0 | L16: =IF(I16=0,"No Capture",IF(I16>1,"Multiple Capture Rows - Review",IF(ABS(K16)<0.01,"Amount Match",IF(K16<0,"Captured Less Than Order","Captured More Than Order")))) -> Amount Match
A17: ORD26000016 | B17: 46273 | C17: CUST24371 | D17: Delhi | E17: Card | F17: 1799 | G17: Paid | H17: =UPPER(SUBSTITUTE(TRIM(A17),"-","")) -> ORD26000016 | I17: =COUNTIFS(PG_Transactions!$AK:$AK,$H17,PG_Transactions!$E:$E,"CAPTURE",PG_Transactions!$AQ:$AQ,1) -> 1 | J17: =SUMIFS(PG_Transactions!$G:$G,PG_Transactions!$AK:$AK,$H17,PG_Transactions!$E:$E,"CAPTURE",PG_Transactions!$AQ:$AQ,1) -> 1799 | K17: =ROUND(J17-F17,2) -> 0 | L17: =IF(I17=0,"No Capture",IF(I17>1,"Multiple Capture Rows - Review",IF(ABS(K17)<0.01,"Amount Match",IF(K17<0,"Captured Less Than Order","Captured More Than Order")))) -> Amount Match
A18: ORD26000017 | B18: 46286 | C18: CUST60432 | D18: Kolkata | E18: Card | F18: 4999 | G18: Paid | H18: =UPPER(SUBSTITUTE(TRIM(A18),"-","")) -> ORD26000017 | I18: =COUNTIFS(PG_Transactions!$AK:$AK,$H18,PG_Transactions!$E:$E,"CAPTURE",PG_Transactions!$AQ:$AQ,1) -> 1 | J18: =SUMIFS(PG_Transactions!$G:$G,PG_Transactions!$AK:$AK,$H18,PG_Transactions!$E:$E,"CAPTURE",PG_Transactions!$AQ:$AQ,1) -> 4999 | K18: =ROUND(J18-F18,2) -> 0 | L18: =IF(I18=0,"No Capture",IF(I18>1,"Multiple Capture Rows - Review",IF(ABS(K18)<0.01,"Amount Match",IF(K18<0,"Captured Less Than Order","Captured More Than Order")))) -> Amount Match
... A80: ORD26000079 | B80: 46285 | C80: CUST76162 | D80: Kolkata | E80: Card | F80: 4999 | G80: Failed | H80: =UPPER(SUBSTITUTE(TRIM(A80),"-","")) -> ORD26000079 | I80: =COUNTIFS(PG_Transactions!$AK:$AK,$H80,PG_Transactions!$E:$E,"CAPTURE",PG_Transactions!$AQ:$AQ,1) -> 0 | J80: =SUMIFS(PG_Transactions!$G:$G,PG_Transactions!$AK:$AK,$H80,PG_Transactions!$E:$E,"CAPTURE",PG_Transactions!$AQ:$AQ,1) -> 0 | K80: =ROUND(J80-F80,2) -> -4999 | L80: =IF(I80=0,"No Capture",IF(I80>1,"Multiple Capture Rows - Review",IF(ABS(K80)<0.01,"Amount Match",IF(K80<0,"Captured Less Than Order","Captured More Than Order")))) -> No Capture
A81: ORD26000080 | B81: 46292 | C81: CUST43972 | E81: UPI | F81: 1998 | G81: Paid | H81: =UPPER(SUBSTITUTE(TRIM(A81),"-","")) -> ORD26000080 | I81: =COUNTIFS(PG_Transactions!$AK:$AK,$H81,PG_Transactions!$E:$E,"CAPTURE",PG_Transactions!$AQ:$AQ,1) -> 1 | J81: =SUMIFS(PG_Transactions!$G:$G,PG_Transactions!$AK:$AK,$H81,PG_Transactions!$E:$E,"CAPTURE",PG_Transactions!$AQ:$AQ,1) -> 1998 | K81: =ROUND(J81-F81,2) -> 0 | L81: =IF(I81=0,"No Capture",IF(I81>1,"Multiple Capture Rows - Review",IF(ABS(K81)<0.01,"Amount Match",IF(K81<0,"Captured Less Than Order","Captured More Than Order")))) -> Amount Match
A82: ORD26000081 | B82: 46292 | C82: CUST45992 | D82: Ahmedabad | E82: Card | F82: 10797 | G82: Paid | H82: =UPPER(SUBSTITUTE(TRIM(A82),"-","")) -> ORD26000081 | I82: =COUNTIFS(PG_Transactions!$AK:$AK,$H82,PG_Transactions!$E:$E,"CAPTURE",PG_Transactions!$AQ:$AQ,1) -> 1 | J82: =SUMIFS(PG_Transactions!$G:$G,PG_Transactions!$AK:$AK,$H82,PG_Transactions!$E:$E,"CAPTURE",PG_Transactions!$AQ:$AQ,1) -> 10797 | K82: =ROUND(J82-F82,2) -> 0 | L82: =IF(I82=0,"No Capture",IF(I82>1,"Multiple Capture Rows - Review",IF(ABS(K82)<0.01,"Amount Match",IF(K82<0,"Captured Less Than Order","Captured More Than Order")))) -> Amount Match
A83: ORD26000082 | B83: 46268 | C83: CUST20561 | D83: Delhi | E83: Wallet | F83: 2197 | G83: Paid | H83: =UPPER(SUBSTITUTE(TRIM(A83),"-","")) -> ORD26000082 | I83: =COUNTIFS(PG_Transactions!$AK:$AK,$H83,PG_Transactions!$E:$E,"CAPTURE",PG_Transactions!$AQ:$AQ,1) -> 1 | J83: =SUMIFS(PG_Transactions!$G:$G,PG_Transactions!$AK:$AK,$H83,PG_Transactions!$E:$E,"CAPTURE",PG_Transactions!$AQ:$AQ,1) -> 2197 | K83: =ROUND(J83-F83,2) -> 0 | L83: =IF(I83=0,"No Capture",IF(I83>1,"Multiple Capture Rows - Review",IF(ABS(K83)<0.01,"Amount Match",IF(K83<0,"Captured Less Than Order","Captured More Than Order")))) -> Amount Match
A84: ORD26000083 | B84: 46270 | C84: CUST18418 | D84: Kolkata | E84: Card | F84: 1299 | G84: Paid | H84: =UPPER(SUBSTITUTE(TRIM(A84),"-","")) -> ORD26000083 | I84: =COUNTIFS(PG_Transactions!$AK:$AK,$H84,PG_Transactions!$E:$E,"CAPTURE",PG_Transactions!$AQ:$AQ,1) -> 1 | J84: =SUMIFS(PG_Transactions!$G:$G,PG_Transactions!$AK:$AK,$H84,PG_Transactions!$E:$E,"CAPTURE",PG_Transactions!$AQ:$AQ,1) -> 1299 | K84: =ROUND(J84-F84,2) -> 0 | L84: =IF(I84=0,"No Capture",IF(I84>1,"Multiple Capture Rows - Review",IF(ABS(K84)<0.01,"Amount Match",IF(K84<0,"Captured Less Than Order","Captured More Than Order")))) -> Amount Match
A85: ORD26000084 | B85: 46279 | C85: CUST65069 | D85: Kolkata | E85: UPI | F85: 1799 | G85: Paid | H85: =UPPER(SUBSTITUTE(TRIM(A85),"-","")) -> ORD26000084 | I85: =COUNTIFS(PG_Transactions!$AK:$AK,$H85,PG_Transactions!$E:$E,"CAPTURE",PG_Transactions!$AQ:$AQ,1) -> 1 | J85: =SUMIFS(PG_Transactions!$G:$G,PG_Transactions!$AK:$AK,$H85,PG_Transactions!$E:$E,"CAPTURE",PG_Transactions!$AQ:$AQ,1) -> 1799 | K85: =ROUND(J85-F85,2) -> 0 | L85: =IF(I85=0,"No Capture",IF(I85>1,"Multiple Capture Rows - Review",IF(ABS(K85)<0.01,"Amount Match",IF(K85<0,"Captured Less Than Order","Captured More Than Order")))) -> Amount Match
A86: ORD26000085 | B86: 46294 | C86: CUST59857 | D86: Ahmedabad | E86: Card | F86: 3798 | G86: Paid | H86: =UPPER(SUBSTITUTE(TRIM(A86),"-","")) -> ORD26000085 | I86: =COUNTIFS(PG_Transactions!$AK:$AK,$H86,PG_Transactions!$E:$E,"CAPTURE",PG_Transactions!$AQ:$AQ,1) -> 1 | J86: =SUMIFS(PG_Transactions!$G:$G,PG_Transactions!$AK:$AK,$H86,PG_Transactions!$E:$E,"CAPTURE",PG_Transactions!$AQ:$AQ,1) -> 3798 | K86: =ROUND(J86-F86,2) -> 0 | L86: =IF(I86=0,"No Capture",IF(I86>1,"Multiple Capture Rows - Review",IF(ABS(K86)<0.01,"Amount Match",IF(K86<0,"Captured Less Than Order","Captured More Than Order")))) -> Amount Match
A87: ORD26000086 | B87: 46266 | C87: CUST64921 | D87: Jaipur | E87: NetBanking | F87: 799 | G87: Paid | H87: =UPPER(SUBSTITUTE(TRIM(A87),"-","")) -> ORD26000086 | I87: =COUNTIFS(PG_Transactions!$AK:$AK,$H87,PG_Transactions!$E:$E,"CAPTURE",PG_Transactions!$AQ:$AQ,1) -> 1 | J87: =SUMIFS(PG_Transactions!$G:$G,PG_Transactions!$AK:$AK,$H87,PG_Transactions!$E:$E,"CAPTURE",PG_Transactions!$AQ:$AQ,1) -> 799 | K87: =ROUND(J87-F87,2) -> 0 | L87: =IF(I87=0,"No Capture",IF(I87>1,"Multiple Capture Rows - Review",IF(ABS(K87)<0.01,"Amount Match",IF(K87<0,"Captured Less Than Order","Captured More Than Order")))) -> Amount Match
A88: ORD26000087 | B88: 46289 | C88: CUST45774 | D88: Kolkata | E88: UPI | F88: 9297 | G88: Failed | H88: =UPPER(SUBSTITUTE(TRIM(A88),"-","")) -> ORD26000087 | I88: =COUNTIFS(PG_Transactions!$AK:$AK,$H88,PG_Transactions!$E:$E,"CAPTURE",PG_Transactions!$AQ:$AQ,1) -> 0 | J88: =SUMIFS(PG_Transactions!$G:$G,PG_Transactions!$AK:$AK,$H88,PG_Transactions!$E:$E,"CAPTURE",PG_Transactions!$AQ:$AQ,1) -> 0 | K88: =ROUND(J88-F88,2) -> -9297 | L88: =IF(I88=0,"No Capture",IF(I88>1,"Multiple Capture Rows - Review",IF(ABS(K88)<0.01,"Amount Match",IF(K88<0,"Captured Less Than Order","Captured More Than Order")))) -> No Capture
A89: ORD26000088 | B89: 46281 | C89: CUST62994 | D89: Delhi | E89: Card | F89: 1299 | G89: Paid | H89: =UPPER(SUBSTITUTE(TRIM(A89),"-","")) -> ORD26000088 | I89: =COUNTIFS(PG_Transactions!$AK:$AK,$H89,PG_Transactions!$E:$E,"CAPTURE",PG_Transactions!$AQ:$AQ,1) -> 1 | J89: =SUMIFS(PG_Transactions!$G:$G,PG_Transactions!$AK:$AK,$H89,PG_Transactions!$E:$E,"CAPTURE",PG_Transactions!$AQ:$AQ,1) -> 1299 | K89: =ROUND(J89-F89,2) -> 0 | L89: =IF(I89=0,"No Capture",IF(I89>1,"Multiple Capture Rows - Review",IF(ABS(K89)<0.01,"Amount Match",IF(K89<0,"Captured Less Than Order","Captured More Than Order")))) -> Amount Match
A90: ORD26000089 | B90: 46292 | C90: CUST87580 | D90: Lucknow | E90: Wallet | F90: 2998 | G90: Paid | H90: =UPPER(SUBSTITUTE(TRIM(A90),"-","")) -> ORD26000089 | I90: =COUNTIFS(PG_Transactions!$AK:$AK,$H90,PG_Transactions!$E:$E,"CAPTURE",PG_Transactions!$AQ:$AQ,1) -> 1 | J90: =SUMIFS(PG_Transactions!$G:$G,PG_Transactions!$AK:$AK,$H90,PG_Transactions!$E:$E,"CAPTURE",PG_Transactions!$AQ:$AQ,1) -> 2998 | K90: =ROUND(J90-F90,2) -> 0 | L90: =IF(I90=0,"No Capture",IF(I90>1,"Multiple Capture Rows - Review",IF(ABS(K90)<0.01,"Amount Match",IF(K90<0,"Captured Less Than Order","Captured More Than Order")))) -> Amount Match
A91: ORD26000090 | B91: 46287 | C91: CUST70515 | D91: Delhi | E91: UPI | F91: 349 | G91: Paid | H91: =UPPER(SUBSTITUTE(TRIM(A91),"-","")) -> ORD26000090 | I91: =COUNTIFS(PG_Transactions!$AK:$AK,$H91,PG_Transactions!$E:$E,"CAPTURE",PG_Transactions!$AQ:$AQ,1) -> 1 | J91: =SUMIFS(PG_Transactions!$G:$G,PG_Transactions!$AK:$AK,$H91,PG_Transactions!$E:$E,"CAPTURE",PG_Transactions!$AQ:$AQ,1) -> 349 | K91: =ROUND(J91-F91,2) -> 0 | L91: =IF(I91=0,"No Capture",IF(I91>1,"Multiple Capture Rows - Review",IF(ABS(K91)<0.01,"Amount Match",IF(K91<0,"Captured Less Than Order","Captured More Than Order")))) -> Amount Match
A92: ORD26000091 | B92: 46267 | C92: CUST54236 | D92: Kolkata | E92: UPI | F92: 1299 | G92: Paid | H92: =UPPER(SUBSTITUTE(TRIM(A92),"-","")) -> ORD26000091 | I92: =COUNTIFS(PG_Transactions!$AK:$AK,$H92,PG_Transactions!$E:$E,"CAPTURE",PG_Transactions!$AQ:$AQ,1) -> 1 | J92: =SUMIFS(PG_Transactions!$G:$G,PG_Transactions!$AK:$AK,$H92,PG_Transactions!$E:$E,"CAPTURE",PG_Transactions!$AQ:$AQ,1) -> 1299 | K92: =ROUND(J92-F92,2) -> 0 | L92: =IF(I92=0,"No Capture",IF(I92>1,"Multiple Capture Rows - Review",IF(ABS(K92)<0.01,"Amount Match",IF(K92<0,"Captured Less Than Order","Captured More Than Order")))) -> Amount Match
A93: ORD26000092 | B93: 46274 | C93: CUST80702 | D93: Mumbai | E93: UPI | F93: 8798 | G93: Paid | H93: =UPPER(SUBSTITUTE(TRIM(A93),"-","")) -> ORD26000092 | I93: =COUNTIFS(PG_Transactions!$AK:$AK,$H93,PG_Transactions!$E:$E,"CAPTURE",PG_Transactions!$AQ:$AQ,1) -> 1 | J93: =SUMIFS(PG_Transactions!$G:$G,PG_Transactions!$AK:$AK,$H93,PG_Transactions!$E:$E,"CAPTURE",PG_Transactions!$AQ:$AQ,1) -> 8798 | K93: =ROUND(J93-F93,2) -> 0 | L93: =IF(I93=0,"No Capture",IF(I93>1,"Multiple Capture Rows - Review",IF(ABS(K93)<0.01,"Amount Match",IF(K93<0,"Captured Less Than Order","Captured More Than Order")))) -> Amount Match
... A126: ORD26000125 | B126: 46269 | C126: CUST28643 | D126: Pune | E126: UPI | F126: 3598 | G126: Paid | H126: =UPPER(SUBSTITUTE(TRIM(A126),"-","")) -> ORD26000125 | I126: =COUNTIFS(PG_Transactions!$AK:$AK,$H126,PG_Transactions!$E:$E,"CAPTURE",PG_Transactions!$AQ:$AQ,1) -> 1 | J126: =SUMIFS(PG_Transactions!$G:$G,PG_Transactions!$AK:$AK,$H126,PG_Transactions!$E:$E,"CAPTURE",PG_Transactions!$AQ:$AQ,1) -> 3598 | K126: =ROUND(J126-F126,2) -> 0 | L126: =IF(I126=0,"No Capture",IF(I126>1,"Multiple Capture Rows - Review",IF(ABS(K126)<0.01,"Amount Match",IF(K126<0,"Captured Less Than Order","Captured More Than Order")))) -> Amount Match
A127: ORD26000126 | B127: 46267 | C127: CUST84607 | E127: Card | F127: 4999 | G127: Paid | H127: =UPPER(SUBSTITUTE(TRIM(A127),"-","")) -> ORD26000126 | I127: =COUNTIFS(PG_Transactions!$AK:$AK,$H127,PG_Transactions!$E:$E,"CAPTURE",PG_Transactions!$AQ:$AQ,1) -> 1 | J127: =SUMIFS(PG_Transactions!$G:$G,PG_Transactions!$AK:$AK,$H127,PG_Transactions!$E:$E,"CAPTURE",PG_Transactions!$AQ:$AQ,1) -> 4999 | K127: =ROUND(J127-F127,2) -> 0 | L127: =IF(I127=0,"No Capture",IF(I127>1,"Multiple Capture Rows - Review",IF(ABS(K127)<0.01,"Amount Match",IF(K127<0,"Captured Less Than Order","Captured More Than Order")))) -> Amount Match
A128: ORD26000127 | B128: 46280 | C128: CUST45683 | D128: Jaipur | E128: Card | F128: 1499 | G128: Paid | H128: =UPPER(SUBSTITUTE(TRIM(A128),"-","")) -> ORD26000127 | I128: =COUNTIFS(PG_Transactions!$AK:$AK,$H128,PG_Transactions!$E:$E,"CAPTURE",PG_Transactions!$AQ:$AQ,1) -> 1 | J128: =SUMIFS(PG_Transactions!$G:$G,PG_Transactions!$AK:$AK,$H128,PG_Transactions!$E:$E,"CAPTURE",PG_Transactions!$AQ:$AQ,1) -> 1499 | K128: =ROUND(J128-F128,2) -> 0 | L128: =IF(I128=0,"No Capture",IF(I128>1,"Multiple Capture Rows - Review",IF(ABS(K128)<0.01,"Amount Match",IF(K128<0,"Captured Less Than Order","Captured More Than Order")))) -> Amount Match
A129: ORD26000128 | B129: 46283 | C129: CUST52247 | D129: Lucknow | E129: Wallet | F129: 1848 | G129: Paid | H129: =UPPER(SUBSTITUTE(TRIM(A129),"-","")) -> ORD26000128 | I129: =COUNTIFS(PG_Transactions!$AK:$AK,$H129,PG_Transactions!$E:$E,"CAPTURE",PG_Transactions!$AQ:$AQ,1) -> 1 | J129: =SUMIFS(PG_Transactions!$G:$G,PG_Transactions!$AK:$AK,$H129,PG_Transactions!$E:$E,"CAPTURE",PG_Transactions!$AQ:$AQ,1) -> 1848 | K129: =ROUND(J129-F129,2) -> 0 | L129: =IF(I129=0,"No Capture",IF(I129>1,"Multiple Capture Rows - Review",IF(ABS(K129)<0.01,"Amount Match",IF(K129<0,"Captured Less Than Order","Captured More Than Order")))) -> Amount Match
A130: ORD26000129 | B130: 46274 | C130: CUST85392 | D130: Lucknow | E130: Card | F130: 349 | G130: Paid | H130: =UPPER(SUBSTITUTE(TRIM(A130),"-","")) -> ORD26000129 | I130: =COUNTIFS(PG_Transactions!$AK:$AK,$H130,PG_Transactions!$E:$E,"CAPTURE",PG_Transactions!$AQ:$AQ,1) -> 1 | J130: =SUMIFS(PG_Transactions!$G:$G,PG_Transactions!$AK:$AK,$H130,PG_Transactions!$E:$E,"CAPTURE",PG_Transactions!$AQ:$AQ,1) -> 349 | K130: =ROUND(J130-F130,2) -> 0 | L130: =IF(I130=0,"No Capture",IF(I130>1,"Multiple Capture Rows - Review",IF(ABS(K130)<0.01,"Amount Match",IF(K130<0,"Captured Less Than Order","Captured More Than Order")))) -> Amount Match
A131: ORD26000130 | B131: 46266 | C131: CUST71669 | D131: Jaipur | E131: Card | F131: 11297 | G131: Paid | H131: =UPPER(SUBSTITUTE(TRIM(A131),"-","")) -> ORD26000130 | I131: =COUNTIFS(PG_Transactions!$AK:$AK,$H131,PG_Transactions!$E:$E,"CAPTURE",PG_Transactions!$AQ:$AQ,1) -> 1 | J131: =SUMIFS(PG_Transactions!$G:$G,PG_Transactions!$AK:$AK,$H131,PG_Transactions!$E:$E,"CAPTURE",PG_Transactions!$AQ:$AQ,1) -> 11297 | K131: =ROUND(J131-F131,2) -> 0 | L131: =IF(I131=0,"No Capture",IF(I131>1,"Multiple Capture Rows - Review",IF(ABS(K131)<0.01,"Amount Match",IF(K131<0,"Captured Less Than Order","Captured More Than Order")))) -> Amount Match
A132: ORD26000131 | B132: 46286 | C132: CUST74451 | D132: Pune | E132: UPI | F132: 1298 | G132: Refunded | H132: =UPPER(SUBSTITUTE(TRIM(A132),"-","")) -> ORD26000131 | I132: =COUNTIFS(PG_Transactions!$AK:$AK,$H132,PG_Transactions!$E:$E,"CAPTURE",PG_Transactions!$AQ:$AQ,1) -> 1 | J132: =SUMIFS(PG_Transactions!$G:$G,PG_Transactions!$AK:$AK,$H132,PG_Transactions!$E:$E,"CAPTURE",PG_Transactions!$AQ:$AQ,1) -> 1298 | K132: =ROUND(J132-F132,2) -> 0 | L132: =IF(I132=0,"No Capture",IF(I132>1,"Multiple Capture Rows - Review",IF(ABS(K132)<0.01,"Amount Match",IF(K132<0,"Captured Less Than Order","Captured More Than Order")))) -> Amount Match
A133: ORD26000132 | B133: 46281 | C133: CUST31079 | D133: Chennai | E133: Card | F133: 1299 | G133: Paid | H133: =UPPER(SUBSTITUTE(TRIM(A133),"-","")) -> ORD26000132 | I133: =COUNTIFS(PG_Transactions!$AK:$AK,$H133,PG_Transactions!$E:$E,"CAPTURE",PG_Transactions!$AQ:$AQ,1) -> 1 | J133: =SUMIFS(PG_Transactions!$G:$G,PG_Transactions!$AK:$AK,$H133,PG_Transactions!$E:$E,"CAPTURE",PG_Transactions!$AQ:$AQ,1) -> 1299 | K133: =ROUND(J133-F133,2) -> 0 | L133: =IF(I133=0,"No Capture",IF(I133>1,"Multiple Capture Rows - Review",IF(ABS(K133)<0.01,"Amount Match",IF(K133<0,"Captured Less Than Order","Captured More Than Order")))) -> Amount Match
...

Sheet PG_Transactions
A1: pg_txn_id | B1: original_payment_id | C1: merchant_order_ref | D1: txn_date | E1: txn_type | F1: payment_method | G1: gross_amount | H1: mdr_fee | I1: gst_on_fee | J1: net_amount | K1: settlement_date | L1: settlement_batch_id | M1: Duplicate_Count | N1: Order_Match_Check | O1: Unmatched_Count | P1: Normalized_Match | Q1: Normalized_Unmatched_Count | R1: Transaction_Category | S1: Capture_Count_By_Reference | T1: Transaction Category | U1: Count | V1: Expected_MDR_Pct | W1: Expected_MDR_Fee | X1: Expected_GST | Y1: MDR_Fee_Variance | Z1: GST_Variance | AA1: Rows_With_Duplicate_IDs\ | AB1: Fee Summary | AD1: Distinct_Duplicate_IDs | AE1: Bank_Batch_Match | AF1: Original_Payment_Check | AG1: Refund_Original_Status | AH1: Missing_Original_Capture_Count | AI1: Original_Capture_Amount | AJ1: Refund_Amount_Check | AK1: Normalized_Order_Ref | AL1: Order_Match_Count | AN1: Order Matching Summary | AP1: Capture_Review_Status | AQ1: First_ID_Record | AR1: Refund_Reference_Check
A2: pay_420000065 | C2: ORD26000066 | D2: 46266 | E2: CAPTURE | F2: Wallet | G2: 6798 | H2: 163.15 | I2: 29.37 | J2: 6605.48 | K2: 46268 | L2: STL-20260903 | M2: =COUNTIF($A:$A,A2) -> 1 | N2: =COUNTIF(Orders!$A:$A,C2) -> 1 | O2: =COUNTIF(N2:N5753,0) -> 651 | P2: =COUNTIF(Orders!$H:$H,UPPER(SUBSTITUTE(TRIM(C2),"-",""))) -> 1 | Q2: =COUNTIF(P2:P5753,0) -> 8 | R2: =IF(E2="REFUND","Refund",IF(P2=0,"Unmatched Order Reference","Matched Order Reference")) -> Matched Order Reference | S2: =COUNTIFS($C$2:$C$5753,C2,$E$2:$E$5753,"CAPTURE") -> 1 | T2: Matched Order Reference | U2: =COUNTIF(R2:R5753,T2) -> 5501 | V2: {=IF(E2<>"CAPTURE",0,SUMPRODUCT((MDR_Rates!$A$2:$A$10=F2)*(G2>MDR_Rates!$B$2:$B$10)*((MDR_Rates!$C$2:$C$10="")+(G2<=MDR_Rates!$C$2:$C$10))*MDR_Rates!$D$2:$D$10))} -> 1.7 | W2: =IF(E2<>"CAPTURE",0,ROUND(G2*V2/100,2)) -> 115.57 | X2: =IF(E2<>"CAPTURE",0,ROUND(W2*18/100,2)) -> 20.8 | Y2: =IF(E2<>"CAPTURE",0,ROUND(H2-W2,2)) -> 47.58 | Z2: =IF(E2<>"CAPTURE",0,ROUND(I2-X2,2)) -> 8.57 | AA2: =COUNTIF(M2:M5753,">1") -> 20 | AB2: Total MDR Variance | AC2: =SUM(Y2:Y5753) -> 1004.42 | AD2: {=SUMPRODUCT((M2:M5753>1)/M2:M5753)} -> 10 | AF2: =COUNTIF($A:$A,"pay_420002554") -> 1 | AG2: =IF(E2<>"REFUND","",IF(COUNTIFS($A:$A,B2,$E:$E,"CAPTURE")=0,"Missing Original Capture","Original Capture Found")) | AH2: =COUNTIF(AG2:AG5753,"Missing Original Capture") -> 0 | AI2: =IF(E2="REFUND",_xlfn.MAXIFS($G:$G,$A:$A,B2,$E:$E,"CAPTURE"),"") | AJ2: =IF(E2<>"REFUND","",IF(G2>AI2,"Refund Exceeds Capture",IF(ABS(G2-AI2)<0.01,"Full Refund","Partial Refund"))) | AK2: =UPPER(SUBSTITUTE(TRIM(C2),"-","")) -> ORD26000066 | AL2: =IF(E2<>"CAPTURE","",COUNTIF(Orders!$H:$H,AK2)) -> 1 | AM2: =COUNTIF(E2:E5753,"REFUND") -> 243 | AN2: Capture rows matched to one order | AO2: =COUNTIFS($E$2:$E$5753,"CAPTURE",$AL$2:$AL$5753,1) -> 5501 | AP2: =IF(E2<>"CAPTURE","",IF(M2>1,"Duplicate ID - Review",IF(AL2=0,"Unmatched Order",IF(AL2=1,"Matched to Order","Multiple Order Matches")))) -> Matched to Order | AQ2: =IF(COUNTIF($A$2:A2,A2)=1,1,0) -> 1 | AR2: =COUNTIF($B:$B,"pay_420000300") -> 0
A3: pay_420000121 | C3: ORD-26000130 | D3: 46266 | E3: CAPTURE | F3: Card | G3: 11297 | H3: 180.75 | I3: 32.54 | J3: 11083.71 | K3: 46268 | L3: STL-20260903 | M3: =COUNTIF($A:$A,A3) -> 1 | N3: =COUNTIF(Orders!$A:$A,C3) -> 0 | P3: =COUNTIF(Orders!$H:$H,UPPER(SUBSTITUTE(TRIM(C3),"-",""))) -> 1 | R3: =IF(E3="REFUND","Refund",IF(P3=0,"Unmatched Order Reference","Matched Order Reference")) -> Matched Order Reference | S3: =COUNTIFS($C$2:$C$5753,C3,$E$2:$E$5753,"CAPTURE") -> 1 | T3: Unmatched Order Reference | U3: =COUNTIF(R2:R5753,T3) -> 8 | V3: {=IF(E3<>"CAPTURE",0,SUMPRODUCT((MDR_Rates!$A$2:$A$10=F3)*(G3>MDR_Rates!$B$2:$B$10)*((MDR_Rates!$C$2:$C$10="")+(G3<=MDR_Rates!$C$2:$C$10))*MDR_Rates!$D$2:$D$10))} -> 1.6 | W3: =IF(E3<>"CAPTURE",0,ROUND(G3*V3/100,2)) -> 180.75 | X3: =IF(E3<>"CAPTURE",0,ROUND(W3*18/100,2)) -> 32.54 | Y3: =IF(E3<>"CAPTURE",0,ROUND(H3-W3,2)) -> 0 | Z3: =IF(E3<>"CAPTURE",0,ROUND(I3-X3,2)) -> 0 | AB3: Total GST Variance | AC3: =SUM(Z2:Z5753) -> 180.78 | AF3: =COUNTIFS($A:$A,"pay_420002554",$E:$E,"CAPTURE") -> 1 | AG3: =IF(E3<>"REFUND","",IF(COUNTIFS($A:$A,B3,$E:$E,"CAPTURE")=0,"Missing Original Capture","Original Capture Found")) | AI3: =IF(E3="REFUND",_xlfn.MAXIFS($G:$G,$A:$A,B3,$E:$E,"CAPTURE"),"") | AJ3: =IF(E3<>"REFUND","",IF(G3>AI3,"Refund Exceeds Capture",IF(ABS(G3-AI3)<0.01,"Full Refund","Partial Refund"))) | AK3: =UPPER(SUBSTITUTE(TRIM(C3),"-","")) -> ORD26000130 | AL3: =IF(E3<>"CAPTURE","",COUNTIF(Orders!$H:$H,AK3)) -> 1 | AM3: =SUMIF(E2:E5753,"REFUND",G2:G5753) -> 893888 | AN3: Unmatched capture rows | AO3: =COUNTIFS($E$2:$E$5753,"CAPTURE",$AL$2:$AL$5753,0) -> 8 | AP3: =IF(E3<>"CAPTURE","",IF(M3>1,"Duplicate ID - Review",IF(AL3=0,"Unmatched Order",IF(AL3=1,"Matched to Order","Multiple Order Matches")))) -> Matched to Order | AQ3: =IF(COUNTIF($A$2:A3,A3)=1,1,0) -> 1
A4: pay_420000170 | C4: ORD26000184 | D4: 46266 | E4: CAPTURE | F4: Card | G4: 4999 | H4: 79.98 | I4: 14.4 | J4: 4904.62 | K4: 46268 | L4: STL-20260903 | M4: =COUNTIF($A:$A,A4) -> 1 | N4: =COUNTIF(Orders!$A:$A,C4) -> 1 | P4: =COUNTIF(Orders!$H:$H,UPPER(SUBSTITUTE(TRIM(C4),"-",""))) -> 1 | R4: =IF(E4="REFUND","Refund",IF(P4=0,"Unmatched Order Reference","Matched Order Reference")) -> Matched Order Reference | S4: =COUNTIFS($C$2:$C$5753,C4,$E$2:$E$5753,"CAPTURE") -> 1 | T4: Refund | U4: =COUNTIF(R2:R5753,T4) -> 243 | V4: {=IF(E4<>"CAPTURE",0,SUMPRODUCT((MDR_Rates!$A$2:$A$10=F4)*(G4>MDR_Rates!$B$2:$B$10)*((MDR_Rates!$C$2:$C$10="")+(G4<=MDR_Rates!$C$2:$C$10))*MDR_Rates!$D$2:$D$10))} -> 1.6 | W4: =IF(E4<>"CAPTURE",0,ROUND(G4*V4/100,2)) -> 79.98 | X4: =IF(E4<>"CAPTURE",0,ROUND(W4*18/100,2)) -> 14.4 | Y4: =IF(E4<>"CAPTURE",0,ROUND(H4-W4,2)) -> 0 | Z4: =IF(E4<>"CAPTURE",0,ROUND(I4-X4,2)) -> 0 | AF4: =SUMIFS($G:$G,$A:$A,"pay_420002554",$E:$E,"CAPTURE") -> 1799 | AG4: =IF(E4<>"REFUND","",IF(COUNTIFS($A:$A,B4,$E:$E,"CAPTURE")=0,"Missing Original Capture","Original Capture Found")) | AI4: =IF(E4="REFUND",_xlfn.MAXIFS($G:$G,$A:$A,B4,$E:$E,"CAPTURE"),"") | AJ4: =IF(E4<>"REFUND","",IF(G4>AI4,"Refund Exceeds Capture",IF(ABS(G4-AI4)<0.01,"Full Refund","Partial Refund"))) | AK4: =UPPER(SUBSTITUTE(TRIM(C4),"-","")) -> ORD26000184 | AL4: =IF(E4<>"CAPTURE","",COUNTIF(Orders!$H:$H,AK4)) -> 1 | AM4: =COUNTIF(AJ2:AJ5753,"Refund Exceeds Capture") -> 0 | AN4: Capture rows matching multiple orders | AO4: =COUNTIFS($E$2:$E$5753,"CAPTURE",$AL$2:$AL$5753,">1") -> 0 | AP4: =IF(E4<>"CAPTURE","",IF(M4>1,"Duplicate ID - Review",IF(AL4=0,"Unmatched Order",IF(AL4=1,"Matched to Order","Multiple Order Matches")))) -> Matched to Order | AQ4: =IF(COUNTIF($A$2:A4,A4)=1,1,0) -> 1
A5: pay_420000229 | C5: ORD26000244 | D5: 46266 | E5: CAPTURE | F5: Card | G5: 349 | H5: 6.28 | I5: 1.13 | J5: 341.59 | K5: 46268 | L5: STL-20260903 | M5: =COUNTIF($A:$A,A5) -> 1 | N5: =COUNTIF(Orders!$A:$A,C5) -> 1 | P5: =COUNTIF(Orders!$H:$H,UPPER(SUBSTITUTE(TRIM(C5),"-",""))) -> 1 | Q5: =COUNTIF(P2:P5753,0) -> 8 | R5: =IF(E5="REFUND","Refund",IF(P5=0,"Unmatched Order Reference","Matched Order Reference")) -> Matched Order Reference | S5: =COUNTIFS($C$2:$C$5753,C5,$E$2:$E$5753,"CAPTURE") -> 1 | V5: {=IF(E5<>"CAPTURE",0,SUMPRODUCT((MDR_Rates!$A$2:$A$10=F5)*(G5>MDR_Rates!$B$2:$B$10)*((MDR_Rates!$C$2:$C$10="")+(G5<=MDR_Rates!$C$2:$C$10))*MDR_Rates!$D$2:$D$10))} -> 1.8 | W5: =IF(E5<>"CAPTURE",0,ROUND(G5*V5/100,2)) -> 6.28 | X5: =IF(E5<>"CAPTURE",0,ROUND(W5*18/100,2)) -> 1.13 | Y5: =IF(E5<>"CAPTURE",0,ROUND(H5-W5,2)) -> 0 | Z5: =IF(E5<>"CAPTURE",0,ROUND(I5-X5,2)) -> 0 | AG5: =IF(E5<>"REFUND","",IF(COUNTIFS($A:$A,B5,$E:$E,"CAPTURE")=0,"Missing Original Capture","Original Capture Found")) | AI5: =IF(E5="REFUND",_xlfn.MAXIFS($G:$G,$A:$A,B5,$E:$E,"CAPTURE"),"") | AJ5: =IF(E5<>"REFUND","",IF(G5>AI5,"Refund Exceeds Capture",IF(ABS(G5-AI5)<0.01,"Full Refund","Partial Refund"))) | AK5: =UPPER(SUBSTITUTE(TRIM(C5),"-","")) -> ORD26000244 | AL5: =IF(E5<>"CAPTURE","",COUNTIF(Orders!$H:$H,AK5)) -> 1 | AP5: =IF(E5<>"CAPTURE","",IF(M5>1,"Duplicate ID - Review",IF(AL5=0,"Unmatched Order",IF(AL5=1,"Matched to Order","Multiple Order Matches")))) -> Matched to Order | AQ5: =IF(COUNTIF($A$2:A5,A5)=1,1,0) -> 1
A6: pay_420000236 | C6: ORD26000252 | D6: 46266 | E6: CAPTURE | F6: UPI | G6: 9498 | H6: 28.49 | I6: 5.13 | J6: 9464.38 | K6: 46268 | L6: STL-20260903 | M6: =COUNTIF($A:$A,A6) -> 1 | N6: =COUNTIF(Orders!$A:$A,C6) -> 1 | P6: =COUNTIF(Orders!$H:$H,UPPER(SUBSTITUTE(TRIM(C6),"-",""))) -> 1 | R6: =IF(E6="REFUND","Refund",IF(P6=0,"Unmatched Order Reference","Matched Order Reference")) -> Matched Order Reference | S6: =COUNTIFS($C$2:$C$5753,C6,$E$2:$E$5753,"CAPTURE") -> 1 | T6: Unmatched Gross Amount | U6: =SUMIF(P2:P5753,0,G2:G5753) -> 24992 | V6: {=IF(E6<>"CAPTURE",0,SUMPRODUCT((MDR_Rates!$A$2:$A$10=F6)*(G6>MDR_Rates!$B$2:$B$10)*((MDR_Rates!$C$2:$C$10="")+(G6<=MDR_Rates!$C$2:$C$10))*MDR_Rates!$D$2:$D$10))} -> 0.3 | W6: =IF(E6<>"CAPTURE",0,ROUND(G6*V6/100,2)) -> 28.49 | X6: =IF(E6<>"CAPTURE",0,ROUND(W6*18/100,2)) -> 5.13 | Y6: =IF(E6<>"CAPTURE",0,ROUND(H6-W6,2)) -> 0 | Z6: =IF(E6<>"CAPTURE",0,ROUND(I6-X6,2)) -> 0 | AG6: =IF(E6<>"REFUND","",IF(COUNTIFS($A:$A,B6,$E:$E,"CAPTURE")=0,"Missing Original Capture","Original Capture Found")) | AI6: =IF(E6="REFUND",_xlfn.MAXIFS($G:$G,$A:$A,B6,$E:$E,"CAPTURE"),"") | AJ6: =IF(E6<>"REFUND","",IF(G6>AI6,"Refund Exceeds Capture",IF(ABS(G6-AI6)<0.01,"Full Refund","Partial Refund"))) | AK6: =UPPER(SUBSTITUTE(TRIM(C6),"-","")) -> ORD26000252 | AL6: =IF(E6<>"CAPTURE","",COUNTIF(Orders!$H:$H,AK6)) -> 1 | AP6: =IF(E6<>"CAPTURE","",IF(M6>1,"Duplicate ID - Review",IF(AL6=0,"Unmatched Order",IF(AL6=1,"Matched to Order","Multiple Order Matches")))) -> Matched to Order | AQ6: =IF(COUNTIF($A$2:A6,A6)=1,1,0) -> 1
A7: pay_420000249 | C7: ORD26000266 | D7: 46266 | E7: CAPTURE | F7: Card | G7: 7999 | H7: 127.98 | I7: 23.04 | J7: 7847.98 | K7: 46268 | L7: STL-20260903 | M7: =COUNTIF($A:$A,A7) -> 1 | N7: =COUNTIF(Orders!$A:$A,C7) -> 1 | P7: =COUNTIF(Orders!$H:$H,UPPER(SUBSTITUTE(TRIM(C7),"-",""))) -> 1 | R7: =IF(E7="REFUND","Refund",IF(P7=0,"Unmatched Order Reference","Matched Order Reference")) -> Matched Order Reference | S7: =COUNTIFS($C$2:$C$5753,C7,$E$2:$E$5753,"CAPTURE") -> 1 | V7: {=IF(E7<>"CAPTURE",0,SUMPRODUCT((MDR_Rates!$A$2:$A$10=F7)*(G7>MDR_Rates!$B$2:$B$10)*((MDR_Rates!$C$2:$C$10="")+(G7<=MDR_Rates!$C$2:$C$10))*MDR_Rates!$D$2:$D$10))} -> 1.6 | W7: =IF(E7<>"CAPTURE",0,ROUND(G7*V7/100,2)) -> 127.98 | X7: =IF(E7<>"CAPTURE",0,ROUND(W7*18/100,2)) -> 23.04 | Y7: =IF(E7<>"CAPTURE",0,ROUND(H7-W7,2)) -> 0 | Z7: =IF(E7<>"CAPTURE",0,ROUND(I7-X7,2)) -> 0 | AG7: =IF(E7<>"REFUND","",IF(COUNTIFS($A:$A,B7,$E:$E,"CAPTURE")=0,"Missing Original Capture","Original Capture Found")) | AI7: =IF(E7="REFUND",_xlfn.MAXIFS($G:$G,$A:$A,B7,$E:$E,"CAPTURE"),"") | AJ7: =IF(E7<>"REFUND","",IF(G7>AI7,"Refund Exceeds Capture",IF(ABS(G7-AI7)<0.01,"Full Refund","Partial Refund"))) | AK7: =UPPER(SUBSTITUTE(TRIM(C7),"-","")) -> ORD26000266 | AL7: =IF(E7<>"CAPTURE","",COUNTIF(Orders!$H:$H,AK7)) -> 1 | AP7: =IF(E7<>"CAPTURE","",IF(M7>1,"Duplicate ID - Review",IF(AL7=0,"Unmatched Order",IF(AL7=1,"Matched to Order","Multiple Order Matches")))) -> Matched to Order | AQ7: =IF(COUNTIF($A$2:A7,A7)=1,1,0) -> 1
A8: pay_420000316 | C8: ORD26000331 | D8: 46266 | E8: CAPTURE | F8: Card | G8: 1299 | H8: 23.38 | I8: 4.21 | J8: 1271.41 | K8: 46268 | L8: STL-20260903 | M8: =COUNTIF($A:$A,A8) -> 1 | N8: =COUNTIF(Orders!$A:$A,C8) -> 1 | P8: =COUNTIF(Orders!$H:$H,UPPER(SUBSTITUTE(TRIM(C8),"-",""))) -> 1 | R8: =IF(E8="REFUND","Refund",IF(P8=0,"Unmatched Order Reference","Matched Order Reference")) -> Matched Order Reference | S8: =COUNTIFS($C$2:$C$5753,C8,$E$2:$E$5753,"CAPTURE") -> 1 | V8: {=IF(E8<>"CAPTURE",0,SUMPRODUCT((MDR_Rates!$A$2:$A$10=F8)*(G8>MDR_Rates!$B$2:$B$10)*((MDR_Rates!$C$2:$C$10="")+(G8<=MDR_Rates!$C$2:$C$10))*MDR_Rates!$D$2:$D$10))} -> 1.8 | W8: =IF(E8<>"CAPTURE",0,ROUND(G8*V8/100,2)) -> 23.38 | X8: =IF(E8<>"CAPTURE",0,ROUND(W8*18/100,2)) -> 4.21 | Y8: =IF(E8<>"CAPTURE",0,ROUND(H8-W8,2)) -> 0 | Z8: =IF(E8<>"CAPTURE",0,ROUND(I8-X8,2)) -> 0 | AG8: =IF(E8<>"REFUND","",IF(COUNTIFS($A:$A,B8,$E:$E,"CAPTURE")=0,"Missing Original Capture","Original Capture Found")) | AI8: =IF(E8="REFUND",_xlfn.MAXIFS($G:$G,$A:$A,B8,$E:$E,"CAPTURE"),"") | AJ8: =IF(E8<>"REFUND","",IF(G8>AI8,"Refund Exceeds Capture",IF(ABS(G8-AI8)<0.01,"Full Refund","Partial Refund"))) | AK8: =UPPER(SUBSTITUTE(TRIM(C8),"-","")) -> ORD26000331 | AL8: =IF(E8<>"CAPTURE","",COUNTIF(Orders!$H:$H,AK8)) -> 1 | AP8: =IF(E8<>"CAPTURE","",IF(M8>1,"Duplicate ID - Review",IF(AL8=0,"Unmatched Order",IF(AL8=1,"Matched to Order","Multiple Order Matches")))) -> Matched to Order | AQ8: =IF(COUNTIF($A$2:A8,A8)=1,1,0) -> 1
A9: pay_420000355 | C9: ORD26000373 | D9: 46266 | E9: CAPTURE | F9: UPI | G9: 1799 | H9: 0 | I9: 0 | J9: 1799 | K9: 46268 | L9: STL-20260903 | M9: =COUNTIF($A:$A,A9) -> 1 | N9: =COUNTIF(Orders!$A:$A,C9) -> 1 | P9: =COUNTIF(Orders!$H:$H,UPPER(SUBSTITUTE(TRIM(C9),"-",""))) -> 1 | R9: =IF(E9="REFUND","Refund",IF(P9=0,"Unmatched Order Reference","Matched Order Reference")) -> Matched Order Reference | S9: =COUNTIFS($C$2:$C$5753,C9,$E$2:$E$5753,"CAPTURE") -> 1 | V9: {=IF(E9<>"CAPTURE",0,SUMPRODUCT((MDR_Rates!$A$2:$A$10=F9)*(G9>MDR_Rates!$B$2:$B$10)*((MDR_Rates!$C$2:$C$10="")+(G9<=MDR_Rates!$C$2:$C$10))*MDR_Rates!$D$2:$D$10))} -> 0 | W9: =IF(E9<>"CAPTURE",0,ROUND(G9*V9/100,2)) -> 0 | X9: =IF(E9<>"CAPTURE",0,ROUND(W9*18/100,2)) -> 0 | Y9: =IF(E9<>"CAPTURE",0,ROUND(H9-W9,2)) -> 0 | Z9: =IF(E9<>"CAPTURE",0,ROUND(I9-X9,2)) -> 0 | AG9: =IF(E9<>"REFUND","",IF(COUNTIFS($A:$A,B9,$E:$E,"CAPTURE")=0,"Missing Original Capture","Original Capture Found")) | AI9: =IF(E9="REFUND",_xlfn.MAXIFS($G:$G,$A:$A,B9,$E:$E,"CAPTURE"),"") | AJ9: =IF(E9<>"REFUND","",IF(G9>AI9,"Refund Exceeds Capture",IF(ABS(G9-AI9)<0.01,"Full Refund","Partial Refund"))) | AK9: =UPPER(SUBSTITUTE(TRIM(C9),"-","")) -> ORD26000373 | AL9: =IF(E9<>"CAPTURE","",COUNTIF(Orders!$H:$H,AK9)) -> 1 | AP9: =IF(E9<>"CAPTURE","",IF(M9>1,"Duplicate ID - Review",IF(AL9=0,"Unmatched Order",IF(AL9=1,"Matched to Order","Multiple Order Matches")))) -> Matched to Order | AQ9: =IF(COUNTIF($A$2:A9,A9)=1,1,0) -> 1
A10: pay_420000357 | C10: ORD26000375 | D10: 46266 | E10: CAPTURE | F10: UPI | G10: 4298 | H10: 12.89 | I10: 2.32 | J10: 4282.79 | K10: 46268 | L10: STL-20260903 | M10: =COUNTIF($A:$A,A10) -> 1 | N10: =COUNTIF(Orders!$A:$A,C10) -> 1 | P10: =COUNTIF(Orders!$H:$H,UPPER(SUBSTITUTE(TRIM(C10),"-",""))) -> 1 | R10: =IF(E10="REFUND","Refund",IF(P10=0,"Unmatched Order Reference","Matched Order Reference")) -> Matched Order Reference | S10: =COUNTIFS($C$2:$C$5753,C10,$E$2:$E$5753,"CAPTURE") -> 1 | V10: {=IF(E10<>"CAPTURE",0,SUMPRODUCT((MDR_Rates!$A$2:$A$10=F10)*(G10>MDR_Rates!$B$2:$B$10)*((MDR_Rates!$C$2:$C$10="")+(G10<=MDR_Rates!$C$2:$C$10))*MDR_Rates!$D$2:$D$10))} -> 0.3 | W10: =IF(E10<>"CAPTURE",0,ROUND(G10*V10/100,2)) -> 12.89 | X10: =IF(E10<>"CAPTURE",0,ROUND(W10*18/100,2)) -> 2.32 | Y10: =IF(E10<>"CAPTURE",0,ROUND(H10-W10,2)) -> 0 | Z10: =IF(E10<>"CAPTURE",0,ROUND(I10-X10,2)) -> 0 | AG10: =IF(E10<>"REFUND","",IF(COUNTIFS($A:$A,B10,$E:$E,"CAPTURE")=0,"Missing Original Capture","Original Capture Found")) | AI10: =IF(E10="REFUND",_xlfn.MAXIFS($G:$G,$A:$A,B10,$E:$E,"CAPTURE"),"") | AJ10: =IF(E10<>"REFUND","",IF(G10>AI10,"Refund Exceeds Capture",IF(ABS(G10-AI10)<0.01,"Full Refund","Partial Refund"))) | AK10: =UPPER(SUBSTITUTE(TRIM(C10),"-","")) -> ORD26000375 | AL10: =IF(E10<>"CAPTURE","",COUNTIF(Orders!$H:$H,AK10)) -> 1 | AP10: =IF(E10<>"CAPTURE","",IF(M10>1,"Duplicate ID - Review",IF(AL10=0,"Unmatched Order",IF(AL10=1,"Matched to Order","Multiple Order Matches")))) -> Matched to Order | AQ10: =IF(COUNTIF($A$2:A10,A10)=1,1,0) -> 1
A11: pay_420000392 | C11: ORD26000410 | D11: 46266 | E11: CAPTURE | F11: Card | G11: 799 | H11: 14.38 | I11: 2.59 | J11: 782.03 | K11: 46268 | L11: STL-20260903 | M11: =COUNTIF($A:$A,A11) -> 1 | N11: =COUNTIF(Orders!$A:$A,C11) -> 1 | P11: =COUNTIF(Orders!$H:$H,UPPER(SUBSTITUTE(TRIM(C11),"-",""))) -> 1 | R11: =IF(E11="REFUND","Refund",IF(P11=0,"Unmatched Order Reference","Matched Order Reference")) -> Matched Order Reference | S11: =COUNTIFS($C$2:$C$5753,C11,$E$2:$E$5753,"CAPTURE") -> 1 | V11: {=IF(E11<>"CAPTURE",0,SUMPRODUCT((MDR_Rates!$A$2:$A$10=F11)*(G11>MDR_Rates!$B$2:$B$10)*((MDR_Rates!$C$2:$C$10="")+(G11<=MDR_Rates!$C$2:$C$10))*MDR_Rates!$D$2:$D$10))} -> 1.8 | W11: =IF(E11<>"CAPTURE",0,ROUND(G11*V11/100,2)) -> 14.38 | X11: =IF(E11<>"CAPTURE",0,ROUND(W11*18/100,2)) -> 2.59 | Y11: =IF(E11<>"CAPTURE",0,ROUND(H11-W11,2)) -> 0 | Z11: =IF(E11<>"CAPTURE",0,ROUND(I11-X11,2)) -> 0 | AG11: =IF(E11<>"REFUND","",IF(COUNTIFS($A:$A,B11,$E:$E,"CAPTURE")=0,"Missing Original Capture","Original Capture Found")) | AI11: =IF(E11="REFUND",_xlfn.MAXIFS($G:$G,$A:$A,B11,$E:$E,"CAPTURE"),"") | AJ11: =IF(E11<>"REFUND","",IF(G11>AI11,"Refund Exceeds Capture",IF(ABS(G11-AI11)<0.01,"Full Refund","Partial Refund"))) | AK11: =UPPER(SUBSTITUTE(TRIM(C11),"-","")) -> ORD26000410 | AL11: =IF(E11<>"CAPTURE","",COUNTIF(Orders!$H:$H,AK11)) -> 1 | AP11: =IF(E11<>"CAPTURE","",IF(M11>1,"Duplicate ID - Review",IF(AL11=0,"Unmatched Order",IF(AL11=1,"Matched to Order","Multiple Order Matches")))) -> Matched to Order | AQ11: =IF(COUNTIF($A$2:A11,A11)=1,1,0) -> 1
A12: pay_420000449 | C12: ORD26000470 | D12: 46266 | E12: CAPTURE | F12: Wallet | G12: 4297 | H12: 73.05 | I12: 13.15 | J12: 4210.8 | K12: 46268 | L12: STL-20260903 | M12: =COUNTIF($A:$A,A12) -> 1 | N12: =COUNTIF(Orders!$A:$A,C12) -> 1 | P12: =COUNTIF(Orders!$H:$H,UPPER(SUBSTITUTE(TRIM(C12),"-",""))) -> 1 | R12: =IF(E12="REFUND","Refund",IF(P12=0,"Unmatched Order Reference","Matched Order Reference")) -> Matched Order Reference | S12: =COUNTIFS($C$2:$C$5753,C12,$E$2:$E$5753,"CAPTURE") -> 1 | V12: {=IF(E12<>"CAPTURE",0,SUMPRODUCT((MDR_Rates!$A$2:$A$10=F12)*(G12>MDR_Rates!$B$2:$B$10)*((MDR_Rates!$C$2:$C$10="")+(G12<=MDR_Rates!$C$2:$C$10))*MDR_Rates!$D$2:$D$10))} -> 1.7 | W12: =IF(E12<>"CAPTURE",0,ROUND(G12*V12/100,2)) -> 73.05 | X12: =IF(E12<>"CAPTURE",0,ROUND(W12*18/100,2)) -> 13.15 | Y12: =IF(E12<>"CAPTURE",0,ROUND(H12-W12,2)) -> 0 | Z12: =IF(E12<>"CAPTURE",0,ROUND(I12-X12,2)) -> 0 | AG12: =IF(E12<>"REFUND","",IF(COUNTIFS($A:$A,B12,$E:$E,"CAPTURE")=0,"Missing Original Capture","Original Capture Found")) | AI12: =IF(E12="REFUND",_xlfn.MAXIFS($G:$G,$A:$A,B12,$E:$E,"CAPTURE"),"") | AJ12: =IF(E12<>"REFUND","",IF(G12>AI12,"Refund Exceeds Capture",IF(ABS(G12-AI12)<0.01,"Full Refund","Partial Refund"))) | AK12: =UPPER(SUBSTITUTE(TRIM(C12),"-","")) -> ORD26000470 | AL12: =IF(E12<>"CAPTURE","",COUNTIF(Orders!$H:$H,AK12)) -> 1 | AP12: =IF(E12<>"CAPTURE","",IF(M12>1,"Duplicate ID - Review",IF(AL12=0,"Unmatched Order",IF(AL12=1,"Matched to Order","Multiple Order Matches")))) -> Matched to Order | AQ12: =IF(COUNTIF($A$2:A12,A12)=1,1,0) -> 1
A13: pay_420000460 | C13: ORD26000483 | D13: 46266 | E13: CAPTURE | F13: Card | G13: 898 | H13: 16.16 | I13: 2.91 | J13: 878.93 | K13: 46268 | L13: STL-20260903 | M13: =COUNTIF($A:$A,A13) -> 1 | N13: =COUNTIF(Orders!$A:$A,C13) -> 1 | P13: =COUNTIF(Orders!$H:$H,UPPER(SUBSTITUTE(TRIM(C13),"-",""))) -> 1 | R13: =IF(E13="REFUND","Refund",IF(P13=0,"Unmatched Order Reference","Matched Order Reference")) -> Matched Order Reference | S13: =COUNTIFS($C$2:$C$5753,C13,$E$2:$E$5753,"CAPTURE") -> 1 | V13: {=IF(E13<>"CAPTURE",0,SUMPRODUCT((MDR_Rates!$A$2:$A$10=F13)*(G13>MDR_Rates!$B$2:$B$10)*((MDR_Rates!$C$2:$C$10="")+(G13<=MDR_Rates!$C$2:$C$10))*MDR_Rates!$D$2:$D$10))} -> 1.8 | W13: =IF(E13<>"CAPTURE",0,ROUND(G13*V13/100,2)) -> 16.16 | X13: =IF(E13<>"CAPTURE",0,ROUND(W13*18/100,2)) -> 2.91 | Y13: =IF(E13<>"CAPTURE",0,ROUND(H13-W13,2)) -> 0 | Z13: =IF(E13<>"CAPTURE",0,ROUND(I13-X13,2)) -> 0 | AG13: =IF(E13<>"REFUND","",IF(COUNTIFS($A:$A,B13,$E:$E,"CAPTURE")=0,"Missing Original Capture","Original Capture Found")) | AI13: =IF(E13="REFUND",_xlfn.MAXIFS($G:$G,$A:$A,B13,$E:$E,"CAPTURE"),"") | AJ13: =IF(E13<>"REFUND","",IF(G13>AI13,"Refund Exceeds Capture",IF(ABS(G13-AI13)<0.01,"Full Refund","Partial Refund"))) | AK13: =UPPER(SUBSTITUTE(TRIM(C13),"-","")) -> ORD26000483 | AL13: =IF(E13<>"CAPTURE","",COUNTIF(Orders!$H:$H,AK13)) -> 1 | AP13: =IF(E13<>"CAPTURE","",IF(M13>1,"Duplicate ID - Review",IF(AL13=0,"Unmatched Order",IF(AL13=1,"Matched to Order","Multiple Order Matches")))) -> Matched to Order | AQ13: =IF(COUNTIF($A$2:A13,A13)=1,1,0) -> 1
A14: pay_420000471 | C14: ORD26000494 | D14: 46266 | E14: CAPTURE | F14: Card | G14: 9498 | H14: 151.97 | I14: 27.35 | J14: 9318.68 | K14: 46268 | L14: STL-20260903 | M14: =COUNTIF($A:$A,A14) -> 1 | N14: =COUNTIF(Orders!$A:$A,C14) -> 1 | P14: =COUNTIF(Orders!$H:$H,UPPER(SUBSTITUTE(TRIM(C14),"-",""))) -> 1 | R14: =IF(E14="REFUND","Refund",IF(P14=0,"Unmatched Order Reference","Matched Order Reference")) -> Matched Order Reference | S14: =COUNTIFS($C$2:$C$5753,C14,$E$2:$E$5753,"CAPTURE") -> 1 | V14: {=IF(E14<>"CAPTURE",0,SUMPRODUCT((MDR_Rates!$A$2:$A$10=F14)*(G14>MDR_Rates!$B$2:$B$10)*((MDR_Rates!$C$2:$C$10="")+(G14<=MDR_Rates!$C$2:$C$10))*MDR_Rates!$D$2:$D$10))} -> 1.6 | W14: =IF(E14<>"CAPTURE",0,ROUND(G14*V14/100,2)) -> 151.97 | X14: =IF(E14<>"CAPTURE",0,ROUND(W14*18/100,2)) -> 27.35 | Y14: =IF(E14<>"CAPTURE",0,ROUND(H14-W14,2)) -> 0 | Z14: =IF(E14<>"CAPTURE",0,ROUND(I14-X14,2)) -> 0 | AG14: =IF(E14<>"REFUND","",IF(COUNTIFS($A:$A,B14,$E:$E,"CAPTURE")=0,"Missing Original Capture","Original Capture Found")) | AI14: =IF(E14="REFUND",_xlfn.MAXIFS($G:$G,$A:$A,B14,$E:$E,"CAPTURE"),"") | AJ14: =IF(E14<>"REFUND","",IF(G14>AI14,"Refund Exceeds Capture",IF(ABS(G14-AI14)<0.01,"Full Refund","Partial Refund"))) | AK14: =UPPER(SUBSTITUTE(TRIM(C14),"-","")) -> ORD26000494 | AL14: =IF(E14<>"CAPTURE","",COUNTIF(Orders!$H:$H,AK14)) -> 1 | AP14: =IF(E14<>"CAPTURE","",IF(M14>1,"Duplicate ID - Review",IF(AL14=0,"Unmatched Order",IF(AL14=1,"Matched to Order","Multiple Order Matches")))) -> Matched to Order | AQ14: =IF(COUNTIF($A$2:A14,A14)=1,1,0) -> 1
A15: pay_420000489 | C15: ORD26000512 | D15: 46266 | E15: CAPTURE | F15: Card | G15: 1798 | H15: 32.36 | I15: 5.82 | J15: 1759.82 | K15: 46268 | L15: STL-20260903 | M15: =COUNTIF($A:$A,A15) -> 1 | N15: =COUNTIF(Orders!$A:$A,C15) -> 1 | P15: =COUNTIF(Orders!$H:$H,UPPER(SUBSTITUTE(TRIM(C15),"-",""))) -> 1 | R15: =IF(E15="REFUND","Refund",IF(P15=0,"Unmatched Order Reference","Matched Order Reference")) -> Matched Order Reference | S15: =COUNTIFS($C$2:$C$5753,C15,$E$2:$E$5753,"CAPTURE") -> 1 | V15: {=IF(E15<>"CAPTURE",0,SUMPRODUCT((MDR_Rates!$A$2:$A$10=F15)*(G15>MDR_Rates!$B$2:$B$10)*((MDR_Rates!$C$2:$C$10="")+(G15<=MDR_Rates!$C$2:$C$10))*MDR_Rates!$D$2:$D$10))} -> 1.8 | W15: =IF(E15<>"CAPTURE",0,ROUND(G15*V15/100,2)) -> 32.36 | X15: =IF(E15<>"CAPTURE",0,ROUND(W15*18/100,2)) -> 5.82 | Y15: =IF(E15<>"CAPTURE",0,ROUND(H15-W15,2)) -> 0 | Z15: =IF(E15<>"CAPTURE",0,ROUND(I15-X15,2)) -> 0 | AG15: =IF(E15<>"REFUND","",IF(COUNTIFS($A:$A,B15,$E:$E,"CAPTURE")=0,"Missing Original Capture","Original Capture Found")) | AI15: =IF(E15="REFUND",_xlfn.MAXIFS($G:$G,$A:$A,B15,$E:$E,"CAPTURE"),"") | AJ15: =IF(E15<>"REFUND","",IF(G15>AI15,"Refund Exceeds Capture",IF(ABS(G15-AI15)<0.01,"Full Refund","Partial Refund"))) | AK15: =UPPER(SUBSTITUTE(TRIM(C15),"-","")) -> ORD26000512 | AL15: =IF(E15<>"CAPTURE","",COUNTIF(Orders!$H:$H,AK15)) -> 1 | AP15: =IF(E15<>"CAPTURE","",IF(M15>1,"Duplicate ID - Review",IF(AL15=0,"Unmatched Order",IF(AL15=1,"Matched to Order","Multiple Order Matches")))) -> Matched to Order | AQ15: =IF(COUNTIF($A$2:A15,A15)=1,1,0) -> 1
A16: pay_420000525 | C16: ORD26000550 | D16: 46266 | E16: CAPTURE | F16: UPI | G16: 7999 | H16: 24 | I16: 4.32 | J16: 7970.68 | K16: 46268 | L16: STL-20260903 | M16: =COUNTIF($A:$A,A16) -> 1 | N16: =COUNTIF(Orders!$A:$A,C16) -> 1 | P16: =COUNTIF(Orders!$H:$H,UPPER(SUBSTITUTE(TRIM(C16),"-",""))) -> 1 | R16: =IF(E16="REFUND","Refund",IF(P16=0,"Unmatched Order Reference","Matched Order Reference")) -> Matched Order Reference | S16: =COUNTIFS($C$2:$C$5753,C16,$E$2:$E$5753,"CAPTURE") -> 1 | V16: {=IF(E16<>"CAPTURE",0,SUMPRODUCT((MDR_Rates!$A$2:$A$10=F16)*(G16>MDR_Rates!$B$2:$B$10)*((MDR_Rates!$C$2:$C$10="")+(G16<=MDR_Rates!$C$2:$C$10))*MDR_Rates!$D$2:$D$10))} -> 0.3 | W16: =IF(E16<>"CAPTURE",0,ROUND(G16*V16/100,2)) -> 24 | X16: =IF(E16<>"CAPTURE",0,ROUND(W16*18/100,2)) -> 4.32 | Y16: =IF(E16<>"CAPTURE",0,ROUND(H16-W16,2)) -> 0 | Z16: =IF(E16<>"CAPTURE",0,ROUND(I16-X16,2)) -> 0 | AG16: =IF(E16<>"REFUND","",IF(COUNTIFS($A:$A,B16,$E:$E,"CAPTURE")=0,"Missing Original Capture","Original Capture Found")) | AI16: =IF(E16="REFUND",_xlfn.MAXIFS($G:$G,$A:$A,B16,$E:$E,"CAPTURE"),"") | AJ16: =IF(E16<>"REFUND","",IF(G16>AI16,"Refund Exceeds Capture",IF(ABS(G16-AI16)<0.01,"Full Refund","Partial Refund"))) | AK16: =UPPER(SUBSTITUTE(TRIM(C16),"-","")) -> ORD26000550 | AL16: =IF(E16<>"CAPTURE","",COUNTIF(Orders!$H:$H,AK16)) -> 1 | AP16: =IF(E16<>"CAPTURE","",IF(M16>1,"Duplicate ID - Review",IF(AL16=0,"Unmatched Order",IF(AL16=1,"Matched to Order","Multiple Order Matches")))) -> Matched to Order | AQ16: =IF(COUNTIF($A$2:A16,A16)=1,1,0) -> 1
A17: pay_420000584 | C17: ORD26000606 | D17: 46266 | E17: CAPTURE | F17: UPI | G17: 11997 | H17: 35.99 | I17: 6.48 | J17: 11954.53 | K17: 46268 | L17: STL-20260903 | M17: =COUNTIF($A:$A,A17) -> 1 | N17: =COUNTIF(Orders!$A:$A,C17) -> 1 | P17: =COUNTIF(Orders!$H:$H,UPPER(SUBSTITUTE(TRIM(C17),"-",""))) -> 1 | R17: =IF(E17="REFUND","Refund",IF(P17=0,"Unmatched Order Reference","Matched Order Reference")) -> Matched Order Reference | S17: =COUNTIFS($C$2:$C$5753,C17,$E$2:$E$5753,"CAPTURE") -> 1 | V17: {=IF(E17<>"CAPTURE",0,SUMPRODUCT((MDR_Rates!$A$2:$A$10=F17)*(G17>MDR_Rates!$B$2:$B$10)*((MDR_Rates!$C$2:$C$10="")+(G17<=MDR_Rates!$C$2:$C$10))*MDR_Rates!$D$2:$D$10))} -> 0.3 | W17: =IF(E17<>"CAPTURE",0,ROUND(G17*V17/100,2)) -> 35.99 | X17: =IF(E17<>"CAPTURE",0,ROUND(W17*18/100,2)) -> 6.48 | Y17: =IF(E17<>"CAPTURE",0,ROUND(H17-W17,2)) -> 0 | Z17: =IF(E17<>"CAPTURE",0,ROUND(I17-X17,2)) -> 0 | AG17: =IF(E17<>"REFUND","",IF(COUNTIFS($A:$A,B17,$E:$E,"CAPTURE")=0,"Missing Original Capture","Original Capture Found")) | AI17: =IF(E17="REFUND",_xlfn.MAXIFS($G:$G,$A:$A,B17,$E:$E,"CAPTURE"),"") | AJ17: =IF(E17<>"REFUND","",IF(G17>AI17,"Refund Exceeds Capture",IF(ABS(G17-AI17)<0.01,"Full Refund","Partial Refund"))) | AK17: =UPPER(SUBSTITUTE(TRIM(C17),"-","")) -> ORD26000606 | AL17: =IF(E17<>"CAPTURE","",COUNTIF(Orders!$H:$H,AK17)) -> 1 | AP17: =IF(E17<>"CAPTURE","",IF(M17>1,"Duplicate ID - Review",IF(AL17=0,"Unmatched Order",IF(AL17=1,"Matched to Order","Multiple Order Matches")))) -> Matched to Order | AQ17: =IF(COUNTIF($A$2:A17,A17)=1,1,0) -> 1
A18: pay_420000597 | C18: ORD26000619 | D18: 46266 | E18: CAPTURE | F18: Wallet | G18: 999 | H18: 18.98 | I18: 3.42 | J18: 976.6 | K18: 46268 | L18: STL-20260903 | M18: =COUNTIF($A:$A,A18) -> 1 | N18: =COUNTIF(Orders!$A:$A,C18) -> 1 | P18: =COUNTIF(Orders!$H:$H,UPPER(SUBSTITUTE(TRIM(C18),"-",""))) -> 1 | R18: =IF(E18="REFUND","Refund",IF(P18=0,"Unmatched Order Reference","Matched Order Reference")) -> Matched Order Reference | S18: =COUNTIFS($C$2:$C$5753,C18,$E$2:$E$5753,"CAPTURE") -> 1 | V18: {=IF(E18<>"CAPTURE",0,SUMPRODUCT((MDR_Rates!$A$2:$A$10=F18)*(G18>MDR_Rates!$B$2:$B$10)*((MDR_Rates!$C$2:$C$10="")+(G18<=MDR_Rates!$C$2:$C$10))*MDR_Rates!$D$2:$D$10))} -> 1.9 | W18: =IF(E18<>"CAPTURE",0,ROUND(G18*V18/100,2)) -> 18.98 | X18: =IF(E18<>"CAPTURE",0,ROUND(W18*18/100,2)) -> 3.42 | Y18: =IF(E18<>"CAPTURE",0,ROUND(H18-W18,2)) -> 0 | Z18: =IF(E18<>"CAPTURE",0,ROUND(I18-X18,2)) -> 0 | AG18: =IF(E18<>"REFUND","",IF(COUNTIFS($A:$A,B18,$E:$E,"CAPTURE")=0,"Missing Original Capture","Original Capture Found")) | AI18: =IF(E18="REFUND",_xlfn.MAXIFS($G:$G,$A:$A,B18,$E:$E,"CAPTURE"),"") | AJ18: =IF(E18<>"REFUND","",IF(G18>AI18,"Refund Exceeds Capture",IF(ABS(G18-AI18)<0.01,"Full Refund","Partial Refund"))) | AK18: =UPPER(SUBSTITUTE(TRIM(C18),"-","")) -> ORD26000619 | AL18: =IF(E18<>"CAPTURE","",COUNTIF(Orders!$H:$H,AK18)) -> 1 | AP18: =IF(E18<>"CAPTURE","",IF(M18>1,"Duplicate ID - Review",IF(AL18=0,"Unmatched Order",IF(AL18=1,"Matched to Order","Multiple Order Matches")))) -> Matched to Order | AQ18: =IF(COUNTIF($A$2:A18,A18)=1,1,0) -> 1
... A329: pay_420005677 | C329: ORD26005942 | D329: 46267 | E329: CAPTURE | F329: Wallet | G329: 1499 | H329: 28.48 | I329: 5.13 | J329: 1465.39 | K329: 46269 | L329: STL-20260904 | M329: =COUNTIF($A:$A,A329) -> 1 | N329: =COUNTIF(Orders!$A:$A,C329) -> 1 | P329: =COUNTIF(Orders!$H:$H,UPPER(SUBSTITUTE(TRIM(C329),"-",""))) -> 1 | R329: =IF(E329="REFUND","Refund",IF(P329=0,"Unmatched Order Reference","Matched Order Reference")) -> Matched Order Reference | S329: =COUNTIFS($C$2:$C$5753,C329,$E$2:$E$5753,"CAPTURE") -> 1 | V329: {=IF(E329<>"CAPTURE",0,SUMPRODUCT((MDR_Rates!$A$2:$A$10=F329)*(G329>MDR_Rates!$B$2:$B$10)*((MDR_Rates!$C$2:$C$10="")+(G329<=MDR_Rates!$C$2:$C$10))*MDR_Rates!$D$2:$D$10))} -> 1.9 | W329: =IF(E329<>"CAPTURE",0,ROUND(G329*V329/100,2)) -> 28.48 | X329: =IF(E329<>"CAPTURE",0,ROUND(W329*18/100,2)) -> 5.13 | Y329: =IF(E329<>"CAPTURE",0,ROUND(H329-W329,2)) -> 0 | Z329: =IF(E329<>"CAPTURE",0,ROUND(I329-X329,2)) -> 0 | AG329: =IF(E329<>"REFUND","",IF(COUNTIFS($A:$A,B329,$E:$E,"CAPTURE")=0,"Missing Original Capture","Original Capture Found")) | AI329: =IF(E329="REFUND",_xlfn.MAXIFS($G:$G,$A:$A,B329,$E:$E,"CAPTURE"),"") | AJ329: =IF(E329<>"REFUND","",IF(G329>AI329,"Refund Exceeds Capture",IF(ABS(G329-AI329)<0.01,"Full Refund","Partial Refund"))) | AK329: =UPPER(SUBSTITUTE(TRIM(C329),"-","")) -> ORD26005942 | AL329: =IF(E329<>"CAPTURE","",COUNTIF(Orders!$H:$H,AK329)) -> 1 | AP329: =IF(E329<>"CAPTURE","",IF(M329>1,"Duplicate ID - Review",IF(AL329=0,"Unmatched Order",IF(AL329=1,"Matched to Order","Multiple Order Matches")))) -> Matched to Order | AQ329: =IF(COUNTIF($A$2:A329,A329)=1,1,0) -> 1
A330: rfnd_BDDX8L3AAXM0 | B330: pay_420002554 | D330: 46267 | E330: REFUND | F330: Wallet | G330: 1799 | H330: 0 | I330: 0 | J330: -1799 | K330: 46269 | L330: STL-20260904 | M330: =COUNTIF($A:$A,A330) -> 1 | N330: =COUNTIF(Orders!$A:$A,C330) -> 0 | P330: =COUNTIF(Orders!$H:$H,UPPER(SUBSTITUTE(TRIM(C330),"-",""))) -> 1042575 | R330: =IF(E330="REFUND","Refund",IF(P330=0,"Unmatched Order Reference","Matched Order Reference")) -> Refund | S330: =COUNTIFS($C$2:$C$5753,C330,$E$2:$E$5753,"CAPTURE") -> 0 | V330: {=IF(E330<>"CAPTURE",0,SUMPRODUCT((MDR_Rates!$A$2:$A$10=F330)*(G330>MDR_Rates!$B$2:$B$10)*((MDR_Rates!$C$2:$C$10="")+(G330<=MDR_Rates!$C$2:$C$10))*MDR_Rates!$D$2:$D$10))} -> 0 | W330: =IF(E330<>"CAPTURE",0,ROUND(G330*V330/100,2)) -> 0 | X330: =IF(E330<>"CAPTURE",0,ROUND(W330*18/100,2)) -> 0 | Y330: =IF(E330<>"CAPTURE",0,ROUND(H330-W330,2)) -> 0 | Z330: =IF(E330<>"CAPTURE",0,ROUND(I330-X330,2)) -> 0 | AG330: =IF(E330<>"REFUND","",IF(COUNTIFS($A:$A,B330,$E:$E,"CAPTURE")=0,"Missing Original Capture","Original Capture Found")) -> Original Capture Found | AI330: =IF(E330="REFUND",_xlfn.MAXIFS($G:$G,$A:$A,B330,$E:$E,"CAPTURE"),"") -> 1799 | AJ330: =IF(E330<>"REFUND","",IF(G330>AI330,"Refund Exceeds Capture",IF(ABS(G330-AI330)<0.01,"Full Refund","Partial Refund"))) -> Full Refund | AK330: =UPPER(SUBSTITUTE(TRIM(C330),"-","")) | AL330: =IF(E330<>"CAPTURE","",COUNTIF(Orders!$H:$H,AK330)) | AP330: =IF(E330<>"CAPTURE","",IF(M330>1,"Duplicate ID - Review",IF(AL330=0,"Unmatched Order",IF(AL330=1,"Matched to Order","Multiple Order Matches")))) | AQ330: =IF(COUNTIF($A$2:A330,A330)=1,1,0) -> 1
A331: rfnd_W6UU5WJWSTPB | B331: pay_420004896 | D331: 46267 | E331: REFUND | F331: NetBanking | G331: 599 | H331: 0 | I331: 0 | J331: -599 | K331: 46269 | L331: STL-20260904 | M331: =COUNTIF($A:$A,A331) -> 1 | N331: =COUNTIF(Orders!$A:$A,C331) -> 0 | P331: =COUNTIF(Orders!$H:$H,UPPER(SUBSTITUTE(TRIM(C331),"-",""))) -> 1042575 | R331: =IF(E331="REFUND","Refund",IF(P331=0,"Unmatched Order Reference","Matched Order Reference")) -> Refund | S331: =COUNTIFS($C$2:$C$5753,C331,$E$2:$E$5753,"CAPTURE") -> 0 | V331: {=IF(E331<>"CAPTURE",0,SUMPRODUCT((MDR_Rates!$A$2:$A$10=F331)*(G331>MDR_Rates!$B$2:$B$10)*((MDR_Rates!$C$2:$C$10="")+(G331<=MDR_Rates!$C$2:$C$10))*MDR_Rates!$D$2:$D$10))} -> 0 | W331: =IF(E331<>"CAPTURE",0,ROUND(G331*V331/100,2)) -> 0 | X331: =IF(E331<>"CAPTURE",0,ROUND(W331*18/100,2)) -> 0 | Y331: =IF(E331<>"CAPTURE",0,ROUND(H331-W331,2)) -> 0 | Z331: =IF(E331<>"CAPTURE",0,ROUND(I331-X331,2)) -> 0 | AG331: =IF(E331<>"REFUND","",IF(COUNTIFS($A:$A,B331,$E:$E,"CAPTURE")=0,"Missing Original Capture","Original Capture Found")) -> Original Capture Found | AI331: =IF(E331="REFUND",_xlfn.MAXIFS($G:$G,$A:$A,B331,$E:$E,"CAPTURE"),"") -> 599 | AJ331: =IF(E331<>"REFUND","",IF(G331>AI331,"Refund Exceeds Capture",IF(ABS(G331-AI331)<0.01,"Full Refund","Partial Refund"))) -> Full Refund | AK331: =UPPER(SUBSTITUTE(TRIM(C331),"-","")) | AL331: =IF(E331<>"CAPTURE","",COUNTIF(Orders!$H:$H,AK331)) | AP331: =IF(E331<>"CAPTURE","",IF(M331>1,"Duplicate ID - Review",IF(AL331=0,"Unmatched Order",IF(AL331=1,"Matched to Order","Multiple Order Matches")))) | AQ331: =IF(COUNTIF($A$2:A331,A331)=1,1,0) -> 1
